<h1><a href="#13-4-自定义包中的错误处理和-panicking" name="13-4-自定义包中的错误处理和-panicking"></a>13.4 自定义包中的错误处理和 panicking</h1>
<p>这是所有自定义包实现者应该遵守的最佳实践：</p>
<p>1）*在包内部，总是应该从 panic 中 recover*：不允许显式的超出包范围的 panic()</p>
<p>2）*向包的调用者返回错误值（而不是 panic）。*</p>
<p>在包内部，特别是在非导出函数中有很深层次的嵌套调用时，将 panic 转换成 error 来告诉调用方为何出错，是很实用的（且提高了代码可读性）。</p>
<p>下面的代码则很好地阐述了这一点。我们有一个简单的 parse 包（示例 13.4）用来把输入的字符串解析为整数切片；这个包有自己特殊的 <code>ParseError</code>。</p>
<p>当没有东西需要转换或者转换成整数失败时，这个包会 panic（在函数 fields2numbers 中）。但是可导出的 Parse 函数会从 panic 中 recover 并用所有这些信息返回一个错误给调用者。为了演示这个过程，在 <a href="examples/chapter_13/panic_recover.go">panic_recover.go</a> 中 调用了 parse 包（示例 13.5）；不可解析的字符串会导致错误并被打印出来。</p>
<p>示例 13.4 <a href="examples/chapter_13/parse/parse.go">parse.go</a>：</p>
<pre><code class="go">// parse.go
package parse

import (
	&quot;fmt&quot;
	&quot;strings&quot;
	&quot;strconv&quot;
)

// A ParseError indicates an error in converting a word into an integer.
type ParseError struct {
    Index int      // The index into the space-separated list of words.
    Word  string   // The word that generated the parse error.
    Err error // The raw error that precipitated this error, if any.
}

// String returns a human-readable error message.
func (e *ParseError) String() string {
    return fmt.Sprintf(&quot;pkg parse: error parsing %q as int&quot;, e.Word)
}

// Parse parses the space-separated words in in put as integers.
func Parse(input string) (numbers []int, err error) {
    defer func() {
        if r := recover(); r != nil {
            var ok bool
            err, ok = r.(error)
            if !ok {
                err = fmt.Errorf(&quot;pkg: %v&quot;, r)
            }
        }
    }()

    fields := strings.Fields(input)
    numbers = fields2numbers(fields)
    return
}

func fields2numbers(fields []string) (numbers []int) {
    if len(fields) == 0 {
        panic(&quot;no words to parse&quot;)
    }
    for idx, field := range fields {
        num, err := strconv.Atoi(field)
        if err != nil {
            panic(&amp;ParseError{idx, field, err})
        }
        numbers = append(numbers, num)
    }
    return
}
</code></pre>
<p>示例 13.5 <a href="examples/chapter_13/panic_package.go">panic_package.go</a>：</p>
<pre><code class="go">// panic_package.go
package main

import (
	&quot;fmt&quot;
	&quot;./parse/parse&quot;
)

func main() {
    var examples = []string{
            &quot;1 2 3 4 5&quot;,
            &quot;100 50 25 12.5 6.25&quot;,
            &quot;2 + 2 = 4&quot;,
            &quot;1st class&quot;,
            &quot;&quot;,
    }

    for _, ex := range examples {
        fmt.Printf(&quot;Parsing %q:\n  &quot;, ex)
        nums, err := parse.Parse(ex)
        if err != nil {
            fmt.Println(err) // here String() method from ParseError is used
            continue
        }
        fmt.Println(nums)
    }
}
</code></pre>
<p>输出：</p>
<pre><code>Parsing &quot;1 2 3 4 5&quot;:
  [1 2 3 4 5]
Parsing &quot;100 50 25 12.5 6.25&quot;:
  pkg: pkg parse: error parsing &quot;12.5&quot; as int
Parsing &quot;2 + 2 = 4&quot;:
  pkg: pkg parse: error parsing &quot;+&quot; as int
Parsing &quot;1st class&quot;:
  pkg: pkg parse: error parsing &quot;1st&quot; as int
Parsing &quot;&quot;:
  pkg: no words to parse
</code></pre>
<h2><a href="#链接" name="链接"></a>链接</h2>
<ul>
  <li><a href="directory.html">目录</a></li>
  <li>上一节：<a href="13.3.html">从 panic 中恢复（Recover）</a></li>
  <li>下一节：<a href="13.5.html">一种用闭包处理错误的模式</a></li>
</ul>